Workbook

Sheet Sheet1
A1: category_type | B1: group_label | C1: source | D1: mean_blended_base | E1: mean_blended_counterfactual | F1: mean_delta_blended | G1: mean_EV_base | H1: mean_EV_counterfactual | I1: mean_delta_EV | J1: total_EV_base | K1: total_EV_counterfactual | L1: total_EV_delta | M1: count
A2: province | B2: AB | C2: ind_only | D2: 0.48425351 | E2: 0.50006262 | F2: 0.015809119 | G2: 640.67461 | H2: 652.89045 | I2: 12.215843 | J2: 53175.993 | K2: 54189.908 | L2: =Sheet1!$K2-Sheet1!$J2 -> 1013.915 | M2: 83
A3: province | B3: BC | C3: ind_only | D3: 0.023621421 | E3: 0.024575844 | F3: 0.00095442241 | G3: 27.3665 | H3: 28.783848 | I3: 1.4173477 | J3: 2709.2835 | K3: 2849.601 | L3: =Sheet1!$K3-Sheet1!$J3 -> 140.31742 | M3: 99
A4: province | B4: MB | C4: ind_only | D4: 0.4123062 | E4: 0.42165814 | F4: 0.0093519368 | G4: 47.580878 | H4: 48.397274 | I4: 0.81639649 | J4: 333.06614 | K4: 338.78092 | L4: =Sheet1!$K4-Sheet1!$J4 -> 5.7147754 | M4: 7
A5: province | B5: Multi | C5: ind_only | D5: 0.42735902 | E5: 0.43960858 | F5: 0.012249558 | G5: 478.59196 | H5: 485.89252 | I5: 7.3005535 | J5: 1435.7759 | K5: 1457.6776 | L5: =Sheet1!$K5-Sheet1!$J5 -> 21.901661 | M5: 3
A6: province | B6: NB | C6: ind_only | D6: 0.34891974 | E6: 0.35030873 | F6: 0.0013889852 | G6: 180.86621 | H6: 182.39409 | I6: 1.5278837 | J6: 723.46484 | K6: 729.57638 | L6: =Sheet1!$K6-Sheet1!$J6 -> 6.111535 | M6: 4
A7: province | B7: NL | C7: ind_only | D7: 0.25411281 | E7: 0.25594016 | F7: 0.001827351 | G7: 386.83572 | H7: 396.90611 | I7: 10.070385 | J7: 3868.3572 | K7: 3969.0611 | L7: =Sheet1!$K7-Sheet1!$J7 -> 100.70385 | M7: 10
A8: province | B8: NS | C8: ind_only | D8: 0.23022101 | E8: 0.24325255 | F8: 0.013031543 | G8: 65.226038 | H8: 67.144313 | I8: 1.9182748 | J8: 913.16454 | K8: 940.02038 | L8: =Sheet1!$K8-Sheet1!$J8 -> 26.855848 | M8: 14
A9: province | B9: NT | C9: ind_only | D9: 0.26084148 | E9: 0.28412485 | F9: 0.023283375 | G9: 48.772232 | H9: 50.979349 | I9: 2.2071163 | J9: 438.95009 | K9: 458.81414 | L9: =Sheet1!$K9-Sheet1!$J9 -> 19.864046 | M9: 9
A10: province | B10: ON | C10: ind_only | D10: 0.44946438 | E10: 0.46060228 | F10: 0.011137892 | G10: 830.2008 | H10: 843.74807 | I10: 13.547278 | J10: 35698.634 | K10: 36281.167 | L10: =Sheet1!$K10-Sheet1!$J10 -> 582.53295 | M10: 43
A11: province | B11: PE | C11: ind_only | D11: 0.43792392 | E11: 0.47636943 | F11: 0.038445507 | G11: 25.620011 | H11: 27.14 | I11: 1.5199889 | J11: 76.860034 | K11: 81.420001 | L11: =Sheet1!$K11-Sheet1!$J11 -> 4.5599668 | M11: 3
A12: province | B12: QC | C12: ind_only | D12: 0.2886445 | E12: 0.29187171 | F12: 0.0032272046 | G12: 197.31763 | H12: 198.68521 | I12: 1.3675793 | J12: 13614.917 | K12: 13709.28 | L12: =Sheet1!$K12-Sheet1!$J12 -> 94.362972 | M12: 69
A13: province | B13: SK | C13: ind_only | D13: 0.301042 | E13: 0.31151329 | F13: 0.01047129 | G13: 155.09803 | H13: 159.21581 | I13: 4.1177845 | J13: 2481.5685 | K13: 2547.453 | L13: =Sheet1!$K13-Sheet1!$J13 -> 65.884552 | M13: 16
A14: province | B14: YK | C14: ind_only | D14: 0.30992732 | E14: 0.30992732 | F14: 0 | G14: 355.94383 | H14: 355.94383 | I14: 0 | J14: 1423.7753 | K14: 1423.7753 | L14: =Sheet1!$K14-Sheet1!$J14 -> 0 | M14: 4
A15: start_year | B15: 0 | C15: ind_only | D15: 0.39909339 | E15: 0.40469427 | F15: 0.0056008841 | G15: 389.34411 | H15: 392.90354 | I15: 3.5594321 | J15: 42438.508 | K15: 42826.486 | L15: =Sheet1!$K15-Sheet1!$J15 -> 387.97809 | M15: 109
A16: start_year | B16: 1 | C16: ind_only | D16: 0.37167712 | E16: 0.37700913 | F16: 0.0053320046 | G16: 423.58153 | H16: 426.77924 | I16: 3.1977148 | J16: 13554.609 | K16: 13656.936 | L16: =Sheet1!$K16-Sheet1!$J16 -> 102.32687 | M16: 32
A17: start_year | B17: 2 | C17: ind_only | D17: 0.38025398 | E17: 0.40053405 | F17: 0.020280077 | G17: 295.96572 | H17: 308.48303 | I17: 12.517312 | J17: 9766.8689 | K17: 10179.94 | L17: =Sheet1!$K17-Sheet1!$J17 -> 413.07129 | M17: 33
A18: start_year | B18: 3 | C18: ind_only | D18: 0.33436647 | E18: 0.35724789 | F18: 0.022881421 | G18: 469.9872 | H18: 482.45166 | I18: 12.464456 | J18: 12689.654 | K18: 13026.195 | L18: =Sheet1!$K18-Sheet1!$J18 -> 336.5403 | M18: 27
A19: start_year | B19: 4 | C19: ind_only | D19: 0.18989399 | E19: 0.21889401 | F19: 0.02900002 | G19: 259.7696 | H19: 288.83194 | I19: 29.062344 | J19: 7533.3184 | K19: 8376.1264 | L19: =Sheet1!$K19-Sheet1!$J19 -> 842.80798 | M19: 29
A20: start_year | B20: 5 | C20: ind_only | D20: 0.11305688 | E20: 0.11305688 | F20: 0 | G20: 78.469905 | H20: 78.469905 | I20: 0 | J20: 1883.2777 | K20: 1883.2777 | L20: =Sheet1!$K20-Sheet1!$J20 -> 0 | M20: 24
A21: start_year | B21: 6 | C21: ind_only | D21: 0.1453079 | E21: 0.1453079 | F21: 0 | G21: 56.601304 | H21: 56.601304 | I21: 0 | J21: 1245.2287 | K21: 1245.2287 | L21: =Sheet1!$K21-Sheet1!$J21 -> 0 | M21: 22
A22: start_year | B22: 7 | C22: ind_only | D22: 0.16400751 | E22: 0.16400751 | F22: 0 | G22: 315.70847 | H22: 315.70847 | I22: 0 | J22: 27782.345 | K22: 27782.345 | L22: =Sheet1!$K22-Sheet1!$J22 -> 0 | M22: 88
A23: sector | B23: Energy | C23: ind_only | D23: 0.36102468 | E23: 0.37155537 | F23: 0.010530691 | G23: 452.14883 | H23: 460.40748 | I23: 8.2586451 | J23: 106254.98 | K23: 108195.76 | L23: =Sheet1!$K23-Sheet1!$J23 -> 1940.7816 | M23: 235
A24: sector | B24: Forest | C24: ind_only | D24: 0.29422879 | E24: 0.30736688 | F24: 0.013138091 | G24: 84.622349 | H24: 87.090873 | I24: 2.468524 | J24: 1438.5799 | K24: 1480.5448 | L24: =Sheet1!$K24-Sheet1!$J24 -> 41.964908 | M24: 17
A25: sector | B25: Mining | C25: ind_only | D25: 0.11587643 | E25: 0.11776127 | F25: 0.0018848389 | G25: 82.145121 | H25: 83.037782 | I25: 0.89266092 | J25: 9200.2535 | K25: 9300.2315 | L25: =Sheet1!$K25-Sheet1!$J25 -> 99.978023 | M25: 112
A26: group | B26: Base Metal | C26: ind_only | D26: 0.1293286 | E26: 0.12964353 | F26: 0.00031492975 | G26: 233.9145 | H26: 233.96647 | I26: 0.051972484 | J26: 1169.5725 | K26: 1169.8324 | L26: =Sheet1!$K26-Sheet1!$J26 -> 0.25986242 | M26: 5
A27: group | B27: CCUS | C27: ind_only | D27: 0.49863541 | E27: 0.50468005 | F27: 0.0060446428 | G27: 2290.6823 | H27: 2302.7065 | I27: 12.024113 | J27: 9162.7294 | K27: 9210.8258 | L27: =Sheet1!$K27-Sheet1!$J27 -> 48.096451 | M27: 4
A28: group | B28: Clean Electricity | C28: ind_only | D28: 0.3958302 | E28: 0.40952931 | F28: 0.013699113 | G28: 307.64529 | H28: 315.02208 | I28: 7.3767905 | J28: 30456.884 | K28: 31187.186 | L28: =Sheet1!$K28-Sheet1!$J28 -> 730.30226 | M28: 99
A29: group | B29: Coal | C29: ind_only | D29: 0.010510053 | E29: 0.010780754 | F29: 0.00027070065 | G29: 9.2595631 | H29: 9.2813006 | I29: 0.021737473 | J29: 111.11476 | K29: 111.37561 | L29: =Sheet1!$K29-Sheet1!$J29 -> 0.26084968 | M29: 12
A30: group | B30: Critical Mineral | C30: ind_only | D30: 0.072083336 | E30: 0.07409399 | F30: 0.0020106544 | G30: 56.110162 | H30: 57.469713 | I30: 1.3595503 | J30: 1627.1947 | K30: 1666.6217 | L30: =Sheet1!$K30-Sheet1!$J30 -> 39.426957 | M30: 29
A31: group | B31: DER, Storage, EV | C31: ind_only | D31: 0.44371437 | E31: 0.47080637 | F31: 0.027092005 | G31: 155.0144 | H31: 163.21533 | I31: 8.2009296 | J31: 1395.1296 | K31: 1468.9379 | L31: =Sheet1!$K31-Sheet1!$J31 -> 73.808367 | M31: 9
A32: group | B32: EWP | C32: ind_only | D32: 0.40665412 | E32: 0.44505887 | F32: 0.038404756 | G32: 162.66165 | H32: 178.02355 | I32: 15.361902 | J32: 162.66165 | K32: 178.02355 | L32: =Sheet1!$K32-Sheet1!$J32 -> 15.361902 | M32: 1
A33: group | B33: Low Carbon Fuels | C33: ind_only | D33: 0.25250979 | E33: 0.25719782 | F33: 0.0046880238 | G33: 229.64775 | H33: 233.08057 | I33: 3.4328164 | J33: 4363.3073 | K33: 4428.5308 | L33: =Sheet1!$K33-Sheet1!$J33 -> 65.223512 | M33: 19
A34: group | B34: Lumber | C34: ind_only | D34: 0.35652365 | E34: 0.43013268 | F34: 0.073609029 | G34: 7.1304731 | H34: 8.6026536 | I34: 1.4721806 | J34: 7.1304731 | K34: 8.6026536 | L34: =Sheet1!$K34-Sheet1!$J34 -> 1.4721806 | M34: 1
... A65: province | B65: YK | C65: mpo_only | D65: 0.30992732 | E65: 0.33272099 | F65: 0.022793668 | G65: 355.94383 | H65: 378.95493 | I65: 23.011102 | J65: 1423.7753 | K65: 1515.8197 | L65: =Sheet1!$K65-Sheet1!$J65 -> 92.044408 | M65: 4
A66: start_year | B66: 1 | C66: mpo_only | D66: 0.39909339 | E66: 0.39909339 | F66: 0 | G66: 389.34411 | H66: 389.34411 | I66: 0 | J66: 42438.508 | K66: 42438.508 | L66: =Sheet1!$K66-Sheet1!$J66 -> 0 | M66: 109
A67: start_year | B67: 2 | C67: mpo_only | D67: 0.23262615 | E67: 0.26056551 | F67: 0.027939359 | G67: 291.98158 | H67: 325.9262 | I67: 33.944626 | J67: 74455.302 | K67: 83111.182 | L67: =Sheet1!$K67-Sheet1!$J67 -> 8655.8796 | M67: 255
A68: sector | B68: Energy | C68: mpo_only | D68: 0.36102468 | E68: 0.38554497 | F68: 0.024520294 | G68: 452.14883 | H68: 486.19984 | I68: 34.051001 | J68: 106254.98 | K68: 114256.96 | L68: =Sheet1!$K68-Sheet1!$J68 -> 8001.9853 | M68: 235
A69: sector | B69: Forest | C69: mpo_only | D69: 0.29422879 | E69: 0.30970514 | F69: 0.015476346 | G69: 84.622349 | H69: 85.84332 | I69: 1.2209711 | J69: 1438.5799 | K69: 1459.3364 | L69: =Sheet1!$K69-Sheet1!$J69 -> 20.756508 | M69: 17
A70: sector | B70: Mining | C70: mpo_only | D70: 0.11587643 | E70: 0.12569045 | F70: 0.0098140155 | G70: 82.145121 | H70: 87.798136 | I70: 5.6530156 | J70: 9200.2535 | K70: 9833.3913 | L70: =Sheet1!$K70-Sheet1!$J70 -> 633.13775 | M70: 112
...

Sheet Sheet2

Sheet Sheet4
A3: Row Labels | B3: Sum of total_EV_delta
A4: combined | B4: 10102.491
A5: sector | B5: 10102.491
A6: Energy | B6: 9323.0183
A7: Forest | B7: 50.95259
A8: Mining | B8: 728.52049
A9: ind_only | B9: 2082.7245
A10: sector | B10: 2082.7245
A11: Energy | B11: 1940.7816
A12: Forest | B12: 41.964908
A13: Mining | B13: 99.978023
A14: mpo_only | B14: 8655.8796
A15: sector | B15: 8655.8796
... A19: Grand Total | B19: 20841.096
