Workbook
Name a: #REF!
Name d: #REF!
Name Database2: #REF!
Name dwa: #REF!
Name IQ_CH: 110000
Name IQ_CQ: 5000
Name IQ_CY: 10000
Name IQ_DAILY: 500000
Name IQ_FH: 100000
Name IQ_FQ: 500
Name IQ_FY: 1000
Name IQ_LTM: 2000
Name IQ_MONTH: 15000
Name IQ_NTM: 6000
Name IQ_WEEK: 50000
Name IQ_YTD: 3000
Name Mining: #REF!
Name qryProjectSearch2: #REF!
Name qryProjectsSearch: #REF!
Name SearchFieldsMajorProjectsInventory: #REF!
Name SearchFieldsMajorProjectsInventory2: #REF!
Name Status: #REF!
Name Status_Change: #REF!

Sheet mpi_dataset_summary_2017-2024
A1: Unique ID | B1: company | C1: project | D1: province | E1: company_type | F1: start_year | G1: end_year | H1: reporting_years | I1: start_status | J1: end_status | K1: current_survival | L1: end_success | M1: project_cost | N1: cost_percentile | O1: latitude_1 | P1: longitude_1 | Q1: sector | R1: group | S1: cleantech | T1: abbreviation
A2: 0 | B2: Bighorn Mining, LTD | C2: Vista Coal Project (Expansion Projects) | D2: AB | E2: Private | F2: 2018 | G2: 2024 | H2: ='mpi_dataset_summary_2017-2024'!$G2-'mpi_dataset_summary_2017-2024'!$F2+1 -> 7 | I2: Announced & Planning | J2: In Review | K2: =IF('mpi_dataset_summary_2017-2024'!$G2=2024,1,0) -> 1 | L2: =IF(J2="Under Construction",1,0) -> 0 | M2: 870 | N2: =_xlfn.PERCENTRANK.INC($M$2:$M$4056,M2) -> 0.789 | O2: 53.33 | P2: -117.53 | Q2: Mining | R2: Coal | S2: No | T2: MIN-COAL
A3: 1 | B3: Premier Renewable Energy | C3: Nicomen Wind Energy Project | D3: BC | E3: Private | F3: 2017 | G3: 2019 | H3: ='mpi_dataset_summary_2017-2024'!$G3-'mpi_dataset_summary_2017-2024'!$F3+1 -> 3 | I3: In Review | J3: In Review | K3: =IF('mpi_dataset_summary_2017-2024'!$G3=2024,1,0) -> 0 | L3: =IF(J3="Under Construction",1,0) -> 0 | M3: 188 | N3: =_xlfn.PERCENTRANK.INC($M$2:$M$4056,M3) -> 0.48 | O3: 50.212613 | P3: -121.38177 | Q3: Energy | R3: Clean Electricity | S3: Yes | T3: EN-CLEL
A4: 2 | B4: 0887572 B.C. Ltd. | C4: Campbell River Power Enterprises | D4: BC | E4: Private | F4: 2017 | G4: 2023 | H4: ='mpi_dataset_summary_2017-2024'!$G4-'mpi_dataset_summary_2017-2024'!$F4+1 -> 7 | I4: Announced & Planning | J4: Announced & Planning | K4: =IF('mpi_dataset_summary_2017-2024'!$G4=2024,1,0) -> 0 | L4: =IF(J4="Under Construction",1,0) -> 0 | M4: 105 | N4: =_xlfn.PERCENTRANK.INC($M$2:$M$4056,M4) -> 0.363 | O4: 50.750359 | P4: -124.88205 | Q4: Energy | R4: Waste Biomass | S4: Yes | T4: EN-BIO
A5: 3 | B5: KGHM Ajax Mining inc. | C5: Ajax Copper-Gold Mine | D5: BC | E5: Private | F5: 2017 | G5: 2017 | H5: ='mpi_dataset_summary_2017-2024'!$G5-'mpi_dataset_summary_2017-2024'!$F5+1 -> 1 | I5: In Review | J5: In Review | K5: =IF('mpi_dataset_summary_2017-2024'!$G5=2024,1,0) -> 0 | L5: =IF(J5="Under Construction",1,0) -> 0 | M5: 1863 | N5: =_xlfn.PERCENTRANK.INC($M$2:$M$4056,M5) -> 0.889 | O5: 50.599801 | P5: -120.44174 | Q5: Mining | R5: Precious Metal | S5: No | T5: MIN-PM
A6: 10 | B6: Aeolis Wind Power Corporation | C6: Hackney Hills Wind Park | D6: BC | E6: Private | F6: 2017 | G6: 2024 | H6: ='mpi_dataset_summary_2017-2024'!$G6-'mpi_dataset_summary_2017-2024'!$F6+1 -> 8 | I6: In Review | J6: In Review | K6: =IF('mpi_dataset_summary_2017-2024'!$G6=2024,1,0) -> 1 | L6: =IF(J6="Under Construction",1,0) -> 0 | M6: 850 | N6: =_xlfn.PERCENTRANK.INC($M$2:$M$4056,M6) -> 0.787 | O6: 56.249263 | P6: -120.84755 | Q6: Energy | R6: Clean Electricity | S6: Yes | T6: EN-CLEL
A7: 11 | B7: Agnico-Eagle Mines Limited | C7: Meliadine | D7: NU | E7: Private | F7: 2017 | G7: 2018 | H7: ='mpi_dataset_summary_2017-2024'!$G7-'mpi_dataset_summary_2017-2024'!$F7+1 -> 2 | I7: Under Construction | J7: Under Construction | K7: =IF('mpi_dataset_summary_2017-2024'!$G7=2024,1,0) -> 0 | L7: =IF(J7="Under Construction",1,0) -> 1 | M7: 1200 | N7: =_xlfn.PERCENTRANK.INC($M$2:$M$4056,M7) -> 0.829 | O7: 63.025 | P7: -92.215 | Q7: Mining | R7: Precious Metal | S7: No | T7: MIN-PM
A8: 19 | B8: Alberta Wind Energy Corp./Mainstream Renewable Power | C8: Windy Point Wind Farm | D8: AB | E8: Private | F8: 2017 | G8: 2020 | H8: ='mpi_dataset_summary_2017-2024'!$G8-'mpi_dataset_summary_2017-2024'!$F8+1 -> 4 | I8: Announced & Planning | J8: Announced & Planning | K8: =IF('mpi_dataset_summary_2017-2024'!$G8=2024,1,0) -> 0 | L8: =IF(J8="Under Construction",1,0) -> 0 | M8: 150 | N8: =_xlfn.PERCENTRANK.INC($M$2:$M$4056,M8) -> 0.442 | O8: 49.485078 | P8: -113.94403 | Q8: Energy | R8: Clean Electricity | S8: Yes | T8: EN-CLEL
A9: 21 | B9: Champion Iron Limited | C9: Kamistiatusset (Kami) | D9: NL | E9: Private | F9: 2017 | G9: 2024 | H9: ='mpi_dataset_summary_2017-2024'!$G9-'mpi_dataset_summary_2017-2024'!$F9+1 -> 8 | I9: Approved | J9: In Review | K9: =IF('mpi_dataset_summary_2017-2024'!$G9=2024,1,0) -> 1 | L9: =IF(J9="Under Construction",1,0) -> 0 | M9: 3864 | N9: =_xlfn.PERCENTRANK.INC($M$2:$M$4056,M9) -> 0.936 | O9: 52.824 | P9: -67.027 | Q9: Mining | R9: Base Metal | S9: No | T9: MIN-BM
A10: 22 | B10: Kinross Gold Corp. (formerly Rockcliff Metals Corp.) | C10: Snow Lake | D10: MB | E10: Private | F10: 2021 | G10: 2024 | H10: ='mpi_dataset_summary_2017-2024'!$G10-'mpi_dataset_summary_2017-2024'!$F10+1 -> 4 | I10: Announced & Planning | J10: Announced & Planning | K10: =IF('mpi_dataset_summary_2017-2024'!$G10=2024,1,0) -> 1 | L10: =IF(J10="Under Construction",1,0) -> 0 | M10: 96.1 | N10: =_xlfn.PERCENTRANK.INC($M$2:$M$4056,M10) -> 0.34 | O10: 54.91 | P10: -100.031 | Q10: Mining | R10: Critical Mineral | S10: Yes | T10: MIN-CM
A11: 26 | B11: Alouette | C11: Expansion d'usine (aluminium) | D11: QC | E11: Private | F11: 2017 | G11: 2021 | H11: ='mpi_dataset_summary_2017-2024'!$G11-'mpi_dataset_summary_2017-2024'!$F11+1 -> 5 | I11: Announced & Planning | J11: Under Construction | K11: =IF('mpi_dataset_summary_2017-2024'!$G11=2024,1,0) -> 0 | L11: =IF(J11="Under Construction",1,0) -> 1 | M11: 2000 | N11: =_xlfn.PERCENTRANK.INC($M$2:$M$4056,M11) -> 0.894 | O11: 50.209428 | P11: -66.382828 | Q11: Mining | R11: Base Metal | S11: No | T11: MIN-BM
A12: 27 | B12: Alta Energy Corp. | C12: Lower Wood River Hydropower Project | D12: BC | E12: Private | F12: 2017 | G12: 2023 | H12: ='mpi_dataset_summary_2017-2024'!$G12-'mpi_dataset_summary_2017-2024'!$F12+1 -> 7 | I12: Announced & Planning | J12: In Review | K12: =IF('mpi_dataset_summary_2017-2024'!$G12=2024,1,0) -> 0 | L12: =IF(J12="Under Construction",1,0) -> 0 | M12: 144 | N12: =_xlfn.PERCENTRANK.INC($M$2:$M$4056,M12) -> 0.435 | O12: 52.008661 | P12: -118.56377 | Q12: Energy | R12: Clean Electricity | S12: Yes | T12: EN-CLEL
A13: 29 | B13: AltaLink | C13: Southern Alberta Transmission Reinforcement | D13: AB | E13: Private | F13: 2017 | G13: 2018 | H13: ='mpi_dataset_summary_2017-2024'!$G13-'mpi_dataset_summary_2017-2024'!$F13+1 -> 2 | I13: Under Construction | J13: Under Construction | K13: =IF('mpi_dataset_summary_2017-2024'!$G13=2024,1,0) -> 0 | L13: =IF(J13="Under Construction",1,0) -> 1 | M13: 1866 | N13: =_xlfn.PERCENTRANK.INC($M$2:$M$4056,M13) -> 0.89 | O13: 49.724368 | P13: -113.39988 | Q13: Energy | R13: Trans & Distr | S13: No | T13: EN-T&D
... A106: 318 | B106: Northeast Utilities, NSTAR, Hydro-Quebec | C106: Transmission Line - Champlain Hudson Power Express | D106: QC | E106: Public | F106: 2017 | G106: 2017 | H106: ='mpi_dataset_summary_2017-2024'!$G106-'mpi_dataset_summary_2017-2024'!$F106+1 -> 1 | I106: In Review | J106: In Review | K106: =IF('mpi_dataset_summary_2017-2024'!$G106=2024,1,0) -> 0 | L106: =IF(J106="Under Construction",1,0) -> 0 | M106: 400 | N106: =_xlfn.PERCENTRANK.INC($M$2:$M$4056,M106) -> 0.635 | O106: 45.56839 | P106: -71.999691 | Q106: Energy | R106: Trans & Distr | S106: No | T106: EN-T&D
A107: 328 | B107: Numerous Companies | C107: COMFIT Program - Wind Energy | D107: NS | E107: Private | F107: 2017 | G107: 2017 | H107: ='mpi_dataset_summary_2017-2024'!$G107-'mpi_dataset_summary_2017-2024'!$F107+1 -> 1 | I107: Under Construction | J107: Under Construction | K107: =IF('mpi_dataset_summary_2017-2024'!$G107=2024,1,0) -> 0 | L107: =IF(J107="Under Construction",1,0) -> 1 | M107: 330 | N107: =_xlfn.PERCENTRANK.INC($M$2:$M$4056,M107) -> 0.595 | Q107: Energy | R107: Clean Electricity | S107: Yes | T107: EN-CLEL
A108: 329 | B108: Northcliff Resources (HDI Mining) | C108: Sisson Project | D108: NB | E108: Private | F108: 2017 | G108: 2024 | H108: ='mpi_dataset_summary_2017-2024'!$G108-'mpi_dataset_summary_2017-2024'!$F108+1 -> 8 | I108: In Review | J108: Approved | K108: =IF('mpi_dataset_summary_2017-2024'!$G108=2024,1,0) -> 1 | L108: =IF(J108="Under Construction",1,0) -> 0 | M108: 579 | N108: =_xlfn.PERCENTRANK.INC($M$2:$M$4056,M108) -> 0.708 | O108: 46.365 | P108: -67.045 | Q108: Mining | R108: Other | S108: No | T108: MIN-OTH
A109: 333 | B109: Ontario Power Generation | C109: Darlington Refurbishment Project | D109: ON | E109: Public | F109: 2017 | G109: 2024 | H109: ='mpi_dataset_summary_2017-2024'!$G109-'mpi_dataset_summary_2017-2024'!$F109+1 -> 8 | I109: Under Construction | J109: Under Construction | K109: =IF('mpi_dataset_summary_2017-2024'!$G109=2024,1,0) -> 1 | L109: =IF(J109="Under Construction",1,0) -> 1 | M109: 12800 | N109: =_xlfn.PERCENTRANK.INC($M$2:$M$4056,M109) -> 0.984 | O109: 43.869869 | P109: -78.719487 | Q109: Energy | R109: Clean Electricity | S109: Yes | T109: EN-LCF
A110: 334 | B110: Ontario Power Generation | C110: The Deep Geologic Repository Project | D110: ON | E110: Public | F110: 2017 | G110: 2019 | H110: ='mpi_dataset_summary_2017-2024'!$G110-'mpi_dataset_summary_2017-2024'!$F110+1 -> 3 | I110: In Review | J110: In Review | K110: =IF('mpi_dataset_summary_2017-2024'!$G110=2024,1,0) -> 0 | L110: =IF(J110="Under Construction",1,0) -> 0 | M110: 2400 | N110: =_xlfn.PERCENTRANK.INC($M$2:$M$4056,M110) -> 0.908 | O110: 44.178018 | P110: -81.63634 | Q110: Energy | R110: Clean Electricity | S110: Yes | T110: EN-LCF
A111: 340 | B111: Oceanic Iron Ore Company | C111: Hopes Advance Iron Mine (Ungava Bay) | D111: QC | E111: Private | F111: 2020 | G111: 2022 | H111: ='mpi_dataset_summary_2017-2024'!$G111-'mpi_dataset_summary_2017-2024'!$F111+1 -> 3 | I111: In Review | J111: Announced & Planning | K111: =IF('mpi_dataset_summary_2017-2024'!$G111=2024,1,0) -> 0 | L111: =IF(J111="Under Construction",1,0) -> 0 | M111: 1566.612 | N111: =_xlfn.PERCENTRANK.INC($M$2:$M$4056,M111) -> 0.871 | O111: 59.310061 | P111: -69.888941 | Q111: Mining | R111: Base Metal | S111: No | T111: MIN-BM
A112: 341 | B112: Osum Oil Sands Corp. | C112: Taiga | D112: AB | E112: Private | F112: 2017 | G112: 2024 | H112: ='mpi_dataset_summary_2017-2024'!$G112-'mpi_dataset_summary_2017-2024'!$F112+1 -> 8 | I112: Approved | J112: Approved | K112: =IF('mpi_dataset_summary_2017-2024'!$G112=2024,1,0) -> 1 | L112: =IF(J112="Under Construction",1,0) -> 0 | M112: 1570 | N112: =_xlfn.PERCENTRANK.INC($M$2:$M$4056,M112) -> 0.872 | O112: 54.680878 | P112: -110.13648 | Q112: Energy | R112: Oil & Gas - Upstream | S112: No | T112: EN-OG-U
A113: 344 | B113: Agnico Eagle Mines Limited | C113: Hammond Reef | D113: ON | E113: Private | F113: 2021 | G113: 2024 | H113: ='mpi_dataset_summary_2017-2024'!$G113-'mpi_dataset_summary_2017-2024'!$F113+1 -> 4 | I113: In Review | J113: Approved | K113: =IF('mpi_dataset_summary_2017-2024'!$G113=2024,1,0) -> 1 | L113: =IF(J113="Under Construction",1,0) -> 0 | M113: 1300 | N113: =_xlfn.PERCENTRANK.INC($M$2:$M$4056,M113) -> 0.843 | O113: 48.88278 | P113: -91.349945 | Q113: Mining | R113: Other | S113: No | T113: MIN-OTH
A114: 345 | B114: Greengen Holdings Ltd | C114: Bremner Creek Hydro Project | D114: BC | E114: Private | F114: 2017 | G114: 2022 | H114: ='mpi_dataset_summary_2017-2024'!$G114-'mpi_dataset_summary_2017-2024'!$F114+1 -> 6 | I114: In Review | J114: Under Construction | K114: =IF('mpi_dataset_summary_2017-2024'!$G114=2024,1,0) -> 0 | L114: =IF(J114="Under Construction",1,0) -> 1 | M114: 230 | N114: =_xlfn.PERCENTRANK.INC($M$2:$M$4056,M114) -> 0.524 | O114: 49.301789 | P114: -121.78959 | Q114: Energy | R114: Clean Electricity | S114: Yes | T114: EN-CLEL
A115: 346 | B115: Woodside, Chevron (Kitimat LNG) | C115: Pacific Trail Pipeline | D115: BC | E115: Private | F115: 2017 | G115: 2021 | H115: ='mpi_dataset_summary_2017-2024'!$G115-'mpi_dataset_summary_2017-2024'!$F115+1 -> 5 | I115: Approved | J115: Approved | K115: =IF('mpi_dataset_summary_2017-2024'!$G115=2024,1,0) -> 0 | L115: =IF(J115="Under Construction",1,0) -> 0 | M115: 1300 | N115: =_xlfn.PERCENTRANK.INC($M$2:$M$4056,M115) -> 0.843 | O115: 54.262315 | P115: -122.62753 | Q115: Energy | R115: Trans & Distr | S115: No | T115: EN-T&D
A116: 347 | B116: Pacific Booker Minerals Inc. | C116: Morrison Copper Gold Project | D116: BC | E116: Private | F116: 2020 | G116: 2020 | H116: ='mpi_dataset_summary_2017-2024'!$G116-'mpi_dataset_summary_2017-2024'!$F116+1 -> 1 | I116: In Review | J116: In Review | K116: =IF('mpi_dataset_summary_2017-2024'!$G116=2024,1,0) -> 0 | L116: =IF(J116="Under Construction",1,0) -> 0 | M116: 517 | N116: =_xlfn.PERCENTRANK.INC($M$2:$M$4056,M116) -> 0.694 | O116: 55.194 | P116: -126.314 | Q116: Mining | R116: Precious Metal | S116: No | T116: MIN-PM
A117: 352 | B117: Brion Energy Corporation (Petro China) | C117: Thickwood/MacKay River | D117: AB | E117: Private | F117: 2017 | G117: 2017 | H117: ='mpi_dataset_summary_2017-2024'!$G117-'mpi_dataset_summary_2017-2024'!$F117+1 -> 1 | I117: Under Construction | J117: Under Construction | K117: =IF('mpi_dataset_summary_2017-2024'!$G117=2024,1,0) -> 0 | L117: =IF(J117="Under Construction",1,0) -> 1 | M117: 4558 | N117: =_xlfn.PERCENTRANK.INC($M$2:$M$4056,M117) -> 0.944 | O117: 56.813402 | P117: -112.15868 | Q117: Energy | R117: Waste Biomass | S117: Yes | T117: EN-BIO
A118: 360 | B118: Polaris Minerals Corp. | C118: Eagle Rock Quarry | D118: BC | E118: Private | F118: 2017 | G118: 2018 | H118: ='mpi_dataset_summary_2017-2024'!$G118-'mpi_dataset_summary_2017-2024'!$F118+1 -> 2 | I118: Announced & Planning | J118: Announced & Planning | K118: =IF('mpi_dataset_summary_2017-2024'!$G118=2024,1,0) -> 0 | L118: =IF(J118="Under Construction",1,0) -> 0 | M118: 115 | N118: =_xlfn.PERCENTRANK.INC($M$2:$M$4056,M118) -> 0.381 | O118: 49.138597 | P118: -124.78271 | Q118: Mining | R118: Other | S118: No | T118: MIN-OTH
A119: 362 | B119: Potash Corporation of Saskatwchewan | C119: Potash Mine Expansion | D119: SK | E119: Private | F119: 2017 | G119: 2017 | H119: ='mpi_dataset_summary_2017-2024'!$G119-'mpi_dataset_summary_2017-2024'!$F119+1 -> 1 | I119: Under Construction | J119: Under Construction | K119: =IF('mpi_dataset_summary_2017-2024'!$G119=2024,1,0) -> 0 | L119: =IF(J119="Under Construction",1,0) -> 1 | M119: 2800 | N119: =_xlfn.PERCENTRANK.INC($M$2:$M$4056,M119) -> 0.918 | O119: 50.471845 | P119: -101.54355 | Q119: Mining | R119: Precious Metal | S119: No | T119: MIN-PM
... A163: 473 | B163: Value Creation Inc. | C163: Tristar' SAGD Pilot Project | D163: AB | E163: Private | F163: 2020 | G163: 2022 | H163: ='mpi_dataset_summary_2017-2024'!$G163-'mpi_dataset_summary_2017-2024'!$F163+1 -> 3 | I163: In Review | J163: In Review | K163: =IF('mpi_dataset_summary_2017-2024'!$G163=2024,1,0) -> 0 | L163: =IF(J163="Under Construction",1,0) -> 0 | M163: 0 | N163: =_xlfn.PERCENTRANK.INC($M$2:$M$4056,M163) -> 0 | O163: 56.571589 | P163: -111.22844 | Q163: Energy | R163: Oil & Gas - Upstream | S163: No | T163: EN-OG-U
A164: 474 | B164: Various project proponents | C164: Local small scale community and First Nations renewable energy projects | D164: NB | E164: Private | F164: 2017 | G164: 2017 | H164: ='mpi_dataset_summary_2017-2024'!$G164-'mpi_dataset_summary_2017-2024'!$F164+1 -> 1 | I164: Under Construction | J164: Under Construction | K164: =IF('mpi_dataset_summary_2017-2024'!$G164=2024,1,0) -> 0 | L164: =IF(J164="Under Construction",1,0) -> 1 | M164: 250 | N164: =_xlfn.PERCENTRANK.INC($M$2:$M$4056,M164) -> 0.535 | Q164: Energy | R164: Clean Electricity | S164: Yes | T164: EN-CLEL
A165: 477 | B165: Victoria Gold Corporation | C165: Dublin Gulch (Eagle Gold) | D165: YK | E165: Private | F165: 2017 | G165: 2020 | H165: ='mpi_dataset_summary_2017-2024'!$G165-'mpi_dataset_summary_2017-2024'!$F165+1 -> 4 | I165: Approved | J165: Under Construction | K165: =IF('mpi_dataset_summary_2017-2024'!$G165=2024,1,0) -> 0 | L165: =IF(J165="Under Construction",1,0) -> 1 | M165: 487 | N165: =_xlfn.PERCENTRANK.INC($M$2:$M$4056,M165) -> 0.676 | O165: 64.02 | P165: -135.818 | Q165: Mining | R165: Precious Metal | S165: No | T165: MIN-PM
A166: 478 | B166: Victory Nickel | C166: Minago | D166: MB | E166: Private | F166: 2017 | G166: 2017 | H166: ='mpi_dataset_summary_2017-2024'!$G166-'mpi_dataset_summary_2017-2024'!$F166+1 -> 1 | I166: Announced & Planning | J166: Announced & Planning | K166: =IF('mpi_dataset_summary_2017-2024'!$G166=2024,1,0) -> 0 | L166: =IF(J166="Under Construction",1,0) -> 0 | M166: 558 | N166: =_xlfn.PERCENTRANK.INC($M$2:$M$4056,M166) -> 0.704 | O166: 54.09 | P166: -99.193 | Q166: Mining | R166: Critical Mineral | S166: Yes | T166: MIN-CM
A167: 481 | B167: Fort St. James Green Energy Limited Partnership | C167: Fort St-James Green Energy Project | D167: BC | E167: Private | F167: 2017 | G167: 2018 | H167: ='mpi_dataset_summary_2017-2024'!$G167-'mpi_dataset_summary_2017-2024'!$F167+1 -> 2 | I167: Under Construction | J167: Under Construction | K167: =IF('mpi_dataset_summary_2017-2024'!$G167=2024,1,0) -> 0 | L167: =IF(J167="Under Construction",1,0) -> 1 | M167: 235 | N167: =_xlfn.PERCENTRANK.INC($M$2:$M$4056,M167) -> 0.527 | O167: 54.444477 | P167: -124.26107 | Q167: Energy | R167: Clean Electricity | S167: Yes | T167: EN-CLEL
A168: 482 | B168: Western Bioenergy Inc. | C168: Merritt Green Energy Project | D168: BC | E168: Private | F168: 2017 | G168: 2018 | H168: ='mpi_dataset_summary_2017-2024'!$G168-'mpi_dataset_summary_2017-2024'!$F168+1 -> 2 | I168: Under Construction | J168: Under Construction | K168: =IF('mpi_dataset_summary_2017-2024'!$G168=2024,1,0) -> 0 | L168: =IF(J168="Under Construction",1,0) -> 1 | M168: 235 | N168: =_xlfn.PERCENTRANK.INC($M$2:$M$4056,M168) -> 0.527 | O168: 50.100761 | P168: -120.79375 | Q168: Energy | R168: Clean Electricity | S168: Yes | T168: EN-CLEL
A169: 484 | B169: Conuma Coal Resources Ltd. | C169: Belcourt/Saxon Coal Mines | D169: BC | E169: Private | F169: 2020 | G169: 2021 | H169: ='mpi_dataset_summary_2017-2024'!$G169-'mpi_dataset_summary_2017-2024'!$F169+1 -> 2 | I169: In Review | J169: In Review | K169: =IF('mpi_dataset_summary_2017-2024'!$G169=2024,1,0) -> 0 | L169: =IF(J169="Under Construction",1,0) -> 0 | M169: 100 | N169: =_xlfn.PERCENTRANK.INC($M$2:$M$4056,M169) -> 0.343 | O169: 54.711929 | P169: -120.95947 | Q169: Mining | R169: Coal | S169: No | T169: MIN-COAL
A170: 485 | B170: Conuma Coal Resources Ltd. | C170: Wolverine Coal Mine (Hermann Deposit) | D170: BC | E170: Private | F170: 2020 | G170: 2024 | H170: ='mpi_dataset_summary_2017-2024'!$G170-'mpi_dataset_summary_2017-2024'!$F170+1 -> 5 | I170: In Review | J170: Approved | K170: =IF('mpi_dataset_summary_2017-2024'!$G170=2024,1,0) -> 1 | L170: =IF(J170="Under Construction",1,0) -> 0 | M170: 55 | N170: =_xlfn.PERCENTRANK.INC($M$2:$M$4056,M170) -> 0.242 | O170: 55.266598 | P170: -120.87158 | Q170: Mining | R170: Coal | S170: No | T170: MIN-COAL
A171: 488 | B171: Western Copper and Gold Corporation | C171: Casino Mine | D171: YK | E171: Private | F171: 2017 | G171: 2024 | H171: ='mpi_dataset_summary_2017-2024'!$G171-'mpi_dataset_summary_2017-2024'!$F171+1 -> 8 | I171: In Review | J171: Announced & Planning | K171: =IF('mpi_dataset_summary_2017-2024'!$G171=2024,1,0) -> 1 | L171: =IF(J171="Under Construction",1,0) -> 0 | M171: 3617 | N171: =_xlfn.PERCENTRANK.INC($M$2:$M$4056,M171) -> 0.933 | O171: 62.739 | P171: -138.823 | Q171: Mining | R171: Precious Metal | S171: No | T171: MIN-PM
A172: 489 | B172: Western GeoPower Corporation - Ram Power Corp. | C172: South Meager Creek Geothermal Project | D172: BC | E172: Private | F172: 2017 | G172: 2017 | H172: ='mpi_dataset_summary_2017-2024'!$G172-'mpi_dataset_summary_2017-2024'!$F172+1 -> 1 | I172: Announced & Planning | J172: Announced & Planning | K172: =IF('mpi_dataset_summary_2017-2024'!$G172=2024,1,0) -> 0 | L172: =IF(J172="Under Construction",1,0) -> 0 | M172: 400 | N172: =_xlfn.PERCENTRANK.INC($M$2:$M$4056,M172) -> 0.635 | O172: 50.527332 | P172: -123.10811 | Q172: Energy | R172: Clean Electricity | S172: Yes | T172: EN-CLEL
A173: 490 | B173: Western Potash | C173: Milestone | D173: SK | E173: Private | F173: 2017 | G173: 2023 | H173: ='mpi_dataset_summary_2017-2024'!$G173-'mpi_dataset_summary_2017-2024'!$F173+1 -> 7 | I173: Approved | J173: Under Construction | K173: =IF('mpi_dataset_summary_2017-2024'!$G173=2024,1,0) -> 0 | L173: =IF(J173="Under Construction",1,0) -> 1 | M173: 149 | N173: =_xlfn.PERCENTRANK.INC($M$2:$M$4056,M173) -> 0.44 | O173: 50.118 | P173: -104.471 | Q173: Mining | R173: Critical Mineral | S173: Yes | T173: MIN-CM
A174: 492 | B174: Wildmare Wind Energy EP | C174: Wildmare Wind Energy Project | D174: BC | E174: Private | F174: 2017 | G174: 2017 | H174: ='mpi_dataset_summary_2017-2024'!$G174-'mpi_dataset_summary_2017-2024'!$F174+1 -> 1 | I174: In Review | J174: In Review | K174: =IF('mpi_dataset_summary_2017-2024'!$G174=2024,1,0) -> 0 | L174: =IF(J174="Under Construction",1,0) -> 0 | M174: 200 | N174: =_xlfn.PERCENTRANK.INC($M$2:$M$4056,M174) -> 0.491 | O174: 55.692287 | P174: -121.79041 | Q174: Energy | R174: Clean Electricity | S174: Yes | T174: EN-CLEL
A175: 499 | B175: Taseko Mines Ltd. | C175: Yellowhead (formerly Harper Creek) | D175: BC | E175: Private | F175: 2020 | G175: 2022 | H175: ='mpi_dataset_summary_2017-2024'!$G175-'mpi_dataset_summary_2017-2024'!$F175+1 -> 3 | I175: In Review | J175: Announced & Planning | K175: =IF('mpi_dataset_summary_2017-2024'!$G175=2024,1,0) -> 0 | L175: =IF(J175="Under Construction",1,0) -> 0 | M175: 1347 | N175: =_xlfn.PERCENTRANK.INC($M$2:$M$4056,M175) -> 0.853 | O175: 51.519 | P175: -119.817 | Q175: Mining | R175: Other | S175: No | T175: MIN-OTH
...
